{
 "cells": [
  {
   "cell_type": "code",
   "execution_count": 1,
   "id": "d42cfafa",
   "metadata": {},
   "outputs": [
    {
     "ename": "ImportError",
     "evalue": "Traceback (most recent call last):\n  File \"/Users/architbubber/venv/lib/python3.9/site-packages/tensorflow/python/pywrap_tensorflow.py\", line 58, in <module>\n    from tensorflow.python.pywrap_tensorflow_internal import *\n  File \"/Users/architbubber/venv/lib/python3.9/site-packages/tensorflow/python/pywrap_tensorflow_internal.py\", line 28, in <module>\n    _pywrap_tensorflow_internal = swig_import_helper()\n  File \"/Users/architbubber/venv/lib/python3.9/site-packages/tensorflow/python/pywrap_tensorflow_internal.py\", line 24, in swig_import_helper\n    _mod = imp.load_module('_pywrap_tensorflow_internal', fp, pathname, description)\n  File \"/opt/homebrew/Cellar/python@3.9/3.9.10/Frameworks/Python.framework/Versions/3.9/lib/python3.9/imp.py\", line 242, in load_module\n    return load_dynamic(name, filename, file)\n  File \"/opt/homebrew/Cellar/python@3.9/3.9.10/Frameworks/Python.framework/Versions/3.9/lib/python3.9/imp.py\", line 342, in load_dynamic\n    return _load(spec)\nImportError: dlopen(/Users/architbubber/venv/lib/python3.9/site-packages/tensorflow/python/_pywrap_tensorflow_internal.so, 0x0006): tried: '/Users/architbubber/venv/lib/python3.9/site-packages/tensorflow/python/_pywrap_tensorflow_internal.so' (mach-o file, but is an incompatible architecture (have 'x86_64', need 'arm64e')), '/usr/local/lib/_pywrap_tensorflow_internal.so' (no such file), '/usr/lib/_pywrap_tensorflow_internal.so' (no such file)\n\n\nFailed to load the native TensorFlow runtime.\n\nSee https://www.tensorflow.org/install/errors\n\nfor some common reasons and solutions.  Include the entire stack trace\nabove this error message when asking for help.",
     "output_type": "error",
     "traceback": [
      "\u001b[0;31m---------------------------------------------------------------------------\u001b[0m",
      "\u001b[0;31mImportError\u001b[0m                               Traceback (most recent call last)",
      "File \u001b[0;32m~/venv/lib/python3.9/site-packages/tensorflow/python/pywrap_tensorflow.py:58\u001b[0m, in \u001b[0;36m<module>\u001b[0;34m\u001b[0m\n\u001b[1;32m     56\u001b[0m   sys\u001b[38;5;241m.\u001b[39msetdlopenflags(_default_dlopen_flags \u001b[38;5;241m|\u001b[39m ctypes\u001b[38;5;241m.\u001b[39mRTLD_LOCAL)\n\u001b[0;32m---> 58\u001b[0m \u001b[38;5;28;01mfrom\u001b[39;00m \u001b[38;5;21;01mtensorflow\u001b[39;00m\u001b[38;5;21;01m.\u001b[39;00m\u001b[38;5;21;01mpython\u001b[39;00m\u001b[38;5;21;01m.\u001b[39;00m\u001b[38;5;21;01mpywrap_tensorflow_internal\u001b[39;00m \u001b[38;5;28;01mimport\u001b[39;00m \u001b[38;5;241m*\u001b[39m\n\u001b[1;32m     59\u001b[0m \u001b[38;5;28;01mfrom\u001b[39;00m \u001b[38;5;21;01mtensorflow\u001b[39;00m\u001b[38;5;21;01m.\u001b[39;00m\u001b[38;5;21;01mpython\u001b[39;00m\u001b[38;5;21;01m.\u001b[39;00m\u001b[38;5;21;01mpywrap_tensorflow_internal\u001b[39;00m \u001b[38;5;28;01mimport\u001b[39;00m __version__\n",
      "File \u001b[0;32m~/venv/lib/python3.9/site-packages/tensorflow/python/pywrap_tensorflow_internal.py:28\u001b[0m, in \u001b[0;36m<module>\u001b[0;34m\u001b[0m\n\u001b[1;32m     27\u001b[0m         \u001b[38;5;28;01mreturn\u001b[39;00m _mod\n\u001b[0;32m---> 28\u001b[0m _pywrap_tensorflow_internal \u001b[38;5;241m=\u001b[39m \u001b[43mswig_import_helper\u001b[49m\u001b[43m(\u001b[49m\u001b[43m)\u001b[49m\n\u001b[1;32m     29\u001b[0m \u001b[38;5;28;01mdel\u001b[39;00m swig_import_helper\n",
      "File \u001b[0;32m~/venv/lib/python3.9/site-packages/tensorflow/python/pywrap_tensorflow_internal.py:24\u001b[0m, in \u001b[0;36mswig_import_helper\u001b[0;34m()\u001b[0m\n\u001b[1;32m     23\u001b[0m \u001b[38;5;28;01mtry\u001b[39;00m:\n\u001b[0;32m---> 24\u001b[0m     _mod \u001b[38;5;241m=\u001b[39m \u001b[43mimp\u001b[49m\u001b[38;5;241;43m.\u001b[39;49m\u001b[43mload_module\u001b[49m\u001b[43m(\u001b[49m\u001b[38;5;124;43m'\u001b[39;49m\u001b[38;5;124;43m_pywrap_tensorflow_internal\u001b[39;49m\u001b[38;5;124;43m'\u001b[39;49m\u001b[43m,\u001b[49m\u001b[43m \u001b[49m\u001b[43mfp\u001b[49m\u001b[43m,\u001b[49m\u001b[43m \u001b[49m\u001b[43mpathname\u001b[49m\u001b[43m,\u001b[49m\u001b[43m \u001b[49m\u001b[43mdescription\u001b[49m\u001b[43m)\u001b[49m\n\u001b[1;32m     25\u001b[0m \u001b[38;5;28;01mfinally\u001b[39;00m:\n",
      "File \u001b[0;32m/opt/homebrew/Cellar/python@3.9/3.9.10/Frameworks/Python.framework/Versions/3.9/lib/python3.9/imp.py:242\u001b[0m, in \u001b[0;36mload_module\u001b[0;34m(name, file, filename, details)\u001b[0m\n\u001b[1;32m    241\u001b[0m     \u001b[38;5;28;01melse\u001b[39;00m:\n\u001b[0;32m--> 242\u001b[0m         \u001b[38;5;28;01mreturn\u001b[39;00m \u001b[43mload_dynamic\u001b[49m\u001b[43m(\u001b[49m\u001b[43mname\u001b[49m\u001b[43m,\u001b[49m\u001b[43m \u001b[49m\u001b[43mfilename\u001b[49m\u001b[43m,\u001b[49m\u001b[43m \u001b[49m\u001b[43mfile\u001b[49m\u001b[43m)\u001b[49m\n\u001b[1;32m    243\u001b[0m \u001b[38;5;28;01melif\u001b[39;00m type_ \u001b[38;5;241m==\u001b[39m PKG_DIRECTORY:\n",
      "File \u001b[0;32m/opt/homebrew/Cellar/python@3.9/3.9.10/Frameworks/Python.framework/Versions/3.9/lib/python3.9/imp.py:342\u001b[0m, in \u001b[0;36mload_dynamic\u001b[0;34m(name, path, file)\u001b[0m\n\u001b[1;32m    340\u001b[0m spec \u001b[38;5;241m=\u001b[39m importlib\u001b[38;5;241m.\u001b[39mmachinery\u001b[38;5;241m.\u001b[39mModuleSpec(\n\u001b[1;32m    341\u001b[0m     name\u001b[38;5;241m=\u001b[39mname, loader\u001b[38;5;241m=\u001b[39mloader, origin\u001b[38;5;241m=\u001b[39mpath)\n\u001b[0;32m--> 342\u001b[0m \u001b[38;5;28;01mreturn\u001b[39;00m \u001b[43m_load\u001b[49m\u001b[43m(\u001b[49m\u001b[43mspec\u001b[49m\u001b[43m)\u001b[49m\n",
      "\u001b[0;31mImportError\u001b[0m: dlopen(/Users/architbubber/venv/lib/python3.9/site-packages/tensorflow/python/_pywrap_tensorflow_internal.so, 0x0006): tried: '/Users/architbubber/venv/lib/python3.9/site-packages/tensorflow/python/_pywrap_tensorflow_internal.so' (mach-o file, but is an incompatible architecture (have 'x86_64', need 'arm64e')), '/usr/local/lib/_pywrap_tensorflow_internal.so' (no such file), '/usr/lib/_pywrap_tensorflow_internal.so' (no such file)",
      "\nDuring handling of the above exception, another exception occurred:\n",
      "\u001b[0;31mImportError\u001b[0m                               Traceback (most recent call last)",
      "Input \u001b[0;32mIn [1]\u001b[0m, in \u001b[0;36m<cell line: 2>\u001b[0;34m()\u001b[0m\n\u001b[1;32m      1\u001b[0m \u001b[38;5;28;01mimport\u001b[39;00m \u001b[38;5;21;01mcv2\u001b[39;00m\n\u001b[0;32m----> 2\u001b[0m \u001b[38;5;28;01mimport\u001b[39;00m \u001b[38;5;21;01mtensorflow\u001b[39;00m \u001b[38;5;28;01mas\u001b[39;00m \u001b[38;5;21;01mtf\u001b[39;00m\n\u001b[1;32m      3\u001b[0m \u001b[38;5;28;01mimport\u001b[39;00m \u001b[38;5;21;01mnumpy\u001b[39;00m \u001b[38;5;28;01mas\u001b[39;00m \u001b[38;5;21;01mnp\u001b[39;00m\n\u001b[1;32m      4\u001b[0m \u001b[38;5;28;01mimport\u001b[39;00m \u001b[38;5;21;01mscipy\u001b[39;00m\u001b[38;5;21;01m.\u001b[39;00m\u001b[38;5;21;01mndimage\u001b[39;00m \u001b[38;5;28;01mas\u001b[39;00m \u001b[38;5;21;01msci\u001b[39;00m\n",
      "File \u001b[0;32m~/venv/lib/python3.9/site-packages/tensorflow/__init__.py:24\u001b[0m, in \u001b[0;36m<module>\u001b[0;34m\u001b[0m\n\u001b[1;32m     21\u001b[0m \u001b[38;5;28;01mimport\u001b[39;00m \u001b[38;5;21;01mos\u001b[39;00m \u001b[38;5;28;01mas\u001b[39;00m \u001b[38;5;21;01m_os\u001b[39;00m\n\u001b[1;32m     23\u001b[0m \u001b[38;5;66;03m# pylint: disable=g-bad-import-order\u001b[39;00m\n\u001b[0;32m---> 24\u001b[0m \u001b[38;5;28;01mfrom\u001b[39;00m \u001b[38;5;21;01mtensorflow\u001b[39;00m\u001b[38;5;21;01m.\u001b[39;00m\u001b[38;5;21;01mpython\u001b[39;00m \u001b[38;5;28;01mimport\u001b[39;00m pywrap_tensorflow  \u001b[38;5;66;03m# pylint: disable=unused-import\u001b[39;00m\n\u001b[1;32m     26\u001b[0m \u001b[38;5;28;01mtry\u001b[39;00m:\n\u001b[1;32m     27\u001b[0m   \u001b[38;5;66;03m# Add `estimator` attribute to allow access to estimator APIs via\u001b[39;00m\n\u001b[1;32m     28\u001b[0m   \u001b[38;5;66;03m# \"tf.estimator...\"\u001b[39;00m\n\u001b[1;32m     29\u001b[0m   \u001b[38;5;28;01mfrom\u001b[39;00m \u001b[38;5;21;01mtensorflow\u001b[39;00m\u001b[38;5;21;01m.\u001b[39;00m\u001b[38;5;21;01mpython\u001b[39;00m\u001b[38;5;21;01m.\u001b[39;00m\u001b[38;5;21;01mestimator\u001b[39;00m\u001b[38;5;21;01m.\u001b[39;00m\u001b[38;5;21;01mapi\u001b[39;00m \u001b[38;5;28;01mimport\u001b[39;00m estimator  \u001b[38;5;66;03m# pylint: disable=g-import-not-at-top\u001b[39;00m\n",
      "File \u001b[0;32m~/venv/lib/python3.9/site-packages/tensorflow/python/__init__.py:49\u001b[0m, in \u001b[0;36m<module>\u001b[0;34m\u001b[0m\n\u001b[1;32m     32\u001b[0m \u001b[38;5;66;03m# TODO(drpng): write up instructions for editing this file in a doc and point to\u001b[39;00m\n\u001b[1;32m     33\u001b[0m \u001b[38;5;66;03m# the doc instead.\u001b[39;00m\n\u001b[1;32m     34\u001b[0m \u001b[38;5;66;03m# If you want to edit this file to expose modules in public tensorflow API, you\u001b[39;00m\n\u001b[0;32m   (...)\u001b[0m\n\u001b[1;32m     44\u001b[0m \u001b[38;5;66;03m# go/tf-wildcard-import\u001b[39;00m\n\u001b[1;32m     45\u001b[0m \u001b[38;5;66;03m# pylint: disable=wildcard-import,g-bad-import-order,g-import-not-at-top\u001b[39;00m\n\u001b[1;32m     47\u001b[0m \u001b[38;5;28;01mimport\u001b[39;00m \u001b[38;5;21;01mnumpy\u001b[39;00m \u001b[38;5;28;01mas\u001b[39;00m \u001b[38;5;21;01mnp\u001b[39;00m\n\u001b[0;32m---> 49\u001b[0m \u001b[38;5;28;01mfrom\u001b[39;00m \u001b[38;5;21;01mtensorflow\u001b[39;00m\u001b[38;5;21;01m.\u001b[39;00m\u001b[38;5;21;01mpython\u001b[39;00m \u001b[38;5;28;01mimport\u001b[39;00m pywrap_tensorflow\n\u001b[1;32m     51\u001b[0m \u001b[38;5;28;01mfrom\u001b[39;00m \u001b[38;5;21;01mtensorflow\u001b[39;00m\u001b[38;5;21;01m.\u001b[39;00m\u001b[38;5;21;01mpython\u001b[39;00m\u001b[38;5;21;01m.\u001b[39;00m\u001b[38;5;21;01mtools\u001b[39;00m \u001b[38;5;28;01mimport\u001b[39;00m component_api_helper\n\u001b[1;32m     52\u001b[0m component_api_helper\u001b[38;5;241m.\u001b[39mpackage_hook(\n\u001b[1;32m     53\u001b[0m     parent_package_str\u001b[38;5;241m=\u001b[39m\u001b[38;5;124m'\u001b[39m\u001b[38;5;124mtensorflow.python\u001b[39m\u001b[38;5;124m'\u001b[39m,\n\u001b[1;32m     54\u001b[0m     child_package_str\u001b[38;5;241m=\u001b[39m(\n\u001b[1;32m     55\u001b[0m         \u001b[38;5;124m'\u001b[39m\u001b[38;5;124mtensorflow_estimator.python.estimator\u001b[39m\u001b[38;5;124m'\u001b[39m))\n",
      "File \u001b[0;32m~/venv/lib/python3.9/site-packages/tensorflow/python/pywrap_tensorflow.py:74\u001b[0m, in \u001b[0;36m<module>\u001b[0;34m\u001b[0m\n\u001b[1;32m     69\u001b[0m \u001b[38;5;28;01mexcept\u001b[39;00m \u001b[38;5;167;01mImportError\u001b[39;00m:\n\u001b[1;32m     70\u001b[0m   msg \u001b[38;5;241m=\u001b[39m \u001b[38;5;124m\"\"\"\u001b[39m\u001b[38;5;132;01m%s\u001b[39;00m\u001b[38;5;130;01m\\n\u001b[39;00m\u001b[38;5;130;01m\\n\u001b[39;00m\u001b[38;5;124mFailed to load the native TensorFlow runtime.\u001b[39m\u001b[38;5;130;01m\\n\u001b[39;00m\n\u001b[1;32m     71\u001b[0m \u001b[38;5;124mSee https://www.tensorflow.org/install/errors\u001b[39m\u001b[38;5;130;01m\\n\u001b[39;00m\n\u001b[1;32m     72\u001b[0m \u001b[38;5;124mfor some common reasons and solutions.  Include the entire stack trace\u001b[39m\n\u001b[1;32m     73\u001b[0m \u001b[38;5;124mabove this error message when asking for help.\u001b[39m\u001b[38;5;124m\"\"\"\u001b[39m \u001b[38;5;241m%\u001b[39m traceback\u001b[38;5;241m.\u001b[39mformat_exc()\n\u001b[0;32m---> 74\u001b[0m   \u001b[38;5;28;01mraise\u001b[39;00m \u001b[38;5;167;01mImportError\u001b[39;00m(msg)\n",
      "\u001b[0;31mImportError\u001b[0m: Traceback (most recent call last):\n  File \"/Users/architbubber/venv/lib/python3.9/site-packages/tensorflow/python/pywrap_tensorflow.py\", line 58, in <module>\n    from tensorflow.python.pywrap_tensorflow_internal import *\n  File \"/Users/architbubber/venv/lib/python3.9/site-packages/tensorflow/python/pywrap_tensorflow_internal.py\", line 28, in <module>\n    _pywrap_tensorflow_internal = swig_import_helper()\n  File \"/Users/architbubber/venv/lib/python3.9/site-packages/tensorflow/python/pywrap_tensorflow_internal.py\", line 24, in swig_import_helper\n    _mod = imp.load_module('_pywrap_tensorflow_internal', fp, pathname, description)\n  File \"/opt/homebrew/Cellar/python@3.9/3.9.10/Frameworks/Python.framework/Versions/3.9/lib/python3.9/imp.py\", line 242, in load_module\n    return load_dynamic(name, filename, file)\n  File \"/opt/homebrew/Cellar/python@3.9/3.9.10/Frameworks/Python.framework/Versions/3.9/lib/python3.9/imp.py\", line 342, in load_dynamic\n    return _load(spec)\nImportError: dlopen(/Users/architbubber/venv/lib/python3.9/site-packages/tensorflow/python/_pywrap_tensorflow_internal.so, 0x0006): tried: '/Users/architbubber/venv/lib/python3.9/site-packages/tensorflow/python/_pywrap_tensorflow_internal.so' (mach-o file, but is an incompatible architecture (have 'x86_64', need 'arm64e')), '/usr/local/lib/_pywrap_tensorflow_internal.so' (no such file), '/usr/lib/_pywrap_tensorflow_internal.so' (no such file)\n\n\nFailed to load the native TensorFlow runtime.\n\nSee https://www.tensorflow.org/install/errors\n\nfor some common reasons and solutions.  Include the entire stack trace\nabove this error message when asking for help."
     ]
    }
   ],
   "source": [
    "import cv2\n",
    "import tensorflow as tf\n",
    "import numpy as np\n",
    "import scipy.ndimage as sci\n",
    "import time\n",
    "import os\n",
    "\n",
    "\n",
    "def resizeIt(img,size=100,median=2):\n",
    "    img=np.float32(img)\n",
    "    r,c=img.shape\n",
    "    resized_img=cv2.resize(img,(size,size))\n",
    "    filtered_img=sci.median_filter(resized_img,median)\n",
    "    return np.uint8(filtered_img)\n",
    "\n",
    "def preprocessing(img0,IMG_SIZE=100):\n",
    "    img_resized=resizeIt(img0,IMG_SIZE,1)\n",
    "    img_blur = cv2.GaussianBlur(img_resized,(5,5),0)\n",
    "    imgTh=cv2.adaptiveThreshold(img_blur,255,cv2.ADAPTIVE_THRESH_GAUSSIAN_C,cv2.THRESH_BINARY,7,3)\n",
    "    ret,img_th = cv2.threshold(imgTh,0,255,cv2.THRESH_TOZERO+cv2.THRESH_OTSU)\n",
    "    return img_th\n",
    "\n",
    "ALPHABET =  ['a','b','c','d','e','f','g','h','i','j','k','l','m','n','o','p','q','r','s','t','u','v','w','x','y','z','1','2','3','4','5','6','7','8','9'] \n",
    "\n",
    "prev=\"\"\n",
    "model = tf.keras.models.load_model(\"model_name.model\")\n",
    "\n",
    "prev_time = time.time()\n",
    "path = \"../dataset_1/A/1003.jpg\"  #Here it picks image while we want live read from camera and continously\n",
    "\n",
    "src = cv2.imread(path)\n",
    "\n",
    "  \n",
    "img_gray = cv2.cvtColor(src, cv2.COLOR_BGR2GRAY)\n",
    "IMG_SIZE = 200\n",
    "\n",
    "img_test = preprocessing(img_gray,IMG_SIZE)\n",
    "\n",
    "cv2.imshow('whole input frame', np.uint8(img_gray))\n",
    "cv2.imshow('qwerty',img_test)\n",
    "    \n",
    "prediction = model.predict([img_test.reshape(-1, IMG_SIZE, IMG_SIZE, 1)])\n",
    "print(prediction)\n",
    "\n",
    "print(prediction[0])\n",
    "    \n",
    "text = ALPHABET[int(np.argmax(prediction[0]))]\n",
    "_ = os.system('cls')\n",
    "print(prediction)\n",
    "\n",
    "print(prediction[0])\n",
    "print('Alphabet: '+text+' Time Required: '+str(time.time()-prev_time))\n",
    "prev_time = time.time()\n",
    "\n"
   ]
  },
  {
   "cell_type": "code",
   "execution_count": null,
   "id": "cd28f505",
   "metadata": {},
   "outputs": [],
   "source": []
  }
 ],
 "metadata": {
  "kernelspec": {
   "display_name": "Python 3 (ipykernel)",
   "language": "python",
   "name": "python3"
  },
  "language_info": {
   "codemirror_mode": {
    "name": "ipython",
    "version": 3
   },
   "file_extension": ".py",
   "mimetype": "text/x-python",
   "name": "python",
   "nbconvert_exporter": "python",
   "pygments_lexer": "ipython3",
   "version": "3.9.10"
  }
 },
 "nbformat": 4,
 "nbformat_minor": 5
}
